2021-01-04 11:38:35,099 ERROR: Exception on /index [GET] [in c:\users\phuhi\onedrive - fpt software\learning\flask\microblog\venv\lib\site-packages\flask\app.py:1891]
Traceback (most recent call last):
  File "c:\users\phuhi\onedrive - fpt software\learning\flask\microblog\venv\lib\site-packages\flask\app.py", line 2447, in wsgi_app
    response = self.full_dispatch_request()
  File "c:\users\phuhi\onedrive - fpt software\learning\flask\microblog\venv\lib\site-packages\flask\app.py", line 1952, in full_dispatch_request
    rv = self.handle_user_exception(e)
  File "c:\users\phuhi\onedrive - fpt software\learning\flask\microblog\venv\lib\site-packages\flask\app.py", line 1821, in handle_user_exception
    reraise(exc_type, exc_value, tb)
  File "c:\users\phuhi\onedrive - fpt software\learning\flask\microblog\venv\lib\site-packages\flask\_compat.py", line 39, in reraise
    raise value
  File "c:\users\phuhi\onedrive - fpt software\learning\flask\microblog\venv\lib\site-packages\flask\app.py", line 1950, in full_dispatch_request
    rv = self.dispatch_request()
  File "c:\users\phuhi\onedrive - fpt software\learning\flask\microblog\venv\lib\site-packages\flask\app.py", line 1936, in dispatch_request
    return self.view_functions[rule.endpoint](**req.view_args)
  File "c:\users\phuhi\onedrive - fpt software\learning\flask\microblog\venv\lib\site-packages\flask_login\utils.py", line 272, in decorated_view
    return func(*args, **kwargs)
  File "C:\Users\phuhi\OneDrive - FPT Software\Learning\Flask\microblog\app\routes.py", line 47, in index
    return render_template('index.html',title = 'Home',form=form,posts = posts.items, next_url=next_url, prev_url=prev_url)
  File "c:\users\phuhi\onedrive - fpt software\learning\flask\microblog\venv\lib\site-packages\flask\templating.py", line 137, in render_template
    return _render(
  File "c:\users\phuhi\onedrive - fpt software\learning\flask\microblog\venv\lib\site-packages\flask\templating.py", line 120, in _render
    rv = template.render(context)
  File "c:\users\phuhi\onedrive - fpt software\learning\flask\microblog\venv\lib\site-packages\jinja2\environment.py", line 1090, in render
    self.environment.handle_exception()
  File "c:\users\phuhi\onedrive - fpt software\learning\flask\microblog\venv\lib\site-packages\jinja2\environment.py", line 832, in handle_exception
    reraise(*rewrite_traceback_stack(source=source))
  File "c:\users\phuhi\onedrive - fpt software\learning\flask\microblog\venv\lib\site-packages\jinja2\_compat.py", line 28, in reraise
    raise value.with_traceback(tb)
  File "C:\Users\phuhi\OneDrive - FPT Software\Learning\Flask\microblog\app\templates\index.html", line 1, in top-level template code
    {% extends "base.html" %}
  File "c:\users\phuhi\onedrive - fpt software\learning\flask\microblog\venv\lib\site-packages\jinja2\environment.py", line 832, in handle_exception
    reraise(*rewrite_traceback_stack(source=source))
  File "c:\users\phuhi\onedrive - fpt software\learning\flask\microblog\venv\lib\site-packages\jinja2\_compat.py", line 28, in reraise
    raise value.with_traceback(tb)
  File "C:\Users\phuhi\OneDrive - FPT Software\Learning\Flask\microblog\app\templates\base.html", line 67, in template
    $(destElem).text("{{ _('Error: Could not contact server) }}");
jinja2.exceptions.TemplateSyntaxError: unexpected char "'" at 2677
2021-01-04 11:38:50,284 ERROR: Exception on / [GET] [in c:\users\phuhi\onedrive - fpt software\learning\flask\microblog\venv\lib\site-packages\flask\app.py:1891]
Traceback (most recent call last):
  File "c:\users\phuhi\onedrive - fpt software\learning\flask\microblog\venv\lib\site-packages\flask\app.py", line 2447, in wsgi_app
    response = self.full_dispatch_request()
  File "c:\users\phuhi\onedrive - fpt software\learning\flask\microblog\venv\lib\site-packages\flask\app.py", line 1952, in full_dispatch_request
    rv = self.handle_user_exception(e)
  File "c:\users\phuhi\onedrive - fpt software\learning\flask\microblog\venv\lib\site-packages\flask\app.py", line 1821, in handle_user_exception
    reraise(exc_type, exc_value, tb)
  File "c:\users\phuhi\onedrive - fpt software\learning\flask\microblog\venv\lib\site-packages\flask\_compat.py", line 39, in reraise
    raise value
  File "c:\users\phuhi\onedrive - fpt software\learning\flask\microblog\venv\lib\site-packages\flask\app.py", line 1950, in full_dispatch_request
    rv = self.dispatch_request()
  File "c:\users\phuhi\onedrive - fpt software\learning\flask\microblog\venv\lib\site-packages\flask\app.py", line 1936, in dispatch_request
    return self.view_functions[rule.endpoint](**req.view_args)
  File "c:\users\phuhi\onedrive - fpt software\learning\flask\microblog\venv\lib\site-packages\flask_login\utils.py", line 272, in decorated_view
    return func(*args, **kwargs)
  File "C:\Users\phuhi\OneDrive - FPT Software\Learning\Flask\microblog\app\routes.py", line 47, in index
    return render_template('index.html',title = 'Home',form=form,posts = posts.items, next_url=next_url, prev_url=prev_url)
  File "c:\users\phuhi\onedrive - fpt software\learning\flask\microblog\venv\lib\site-packages\flask\templating.py", line 137, in render_template
    return _render(
  File "c:\users\phuhi\onedrive - fpt software\learning\flask\microblog\venv\lib\site-packages\flask\templating.py", line 120, in _render
    rv = template.render(context)
  File "c:\users\phuhi\onedrive - fpt software\learning\flask\microblog\venv\lib\site-packages\jinja2\environment.py", line 1090, in render
    self.environment.handle_exception()
  File "c:\users\phuhi\onedrive - fpt software\learning\flask\microblog\venv\lib\site-packages\jinja2\environment.py", line 832, in handle_exception
    reraise(*rewrite_traceback_stack(source=source))
  File "c:\users\phuhi\onedrive - fpt software\learning\flask\microblog\venv\lib\site-packages\jinja2\_compat.py", line 28, in reraise
    raise value.with_traceback(tb)
  File "C:\Users\phuhi\OneDrive - FPT Software\Learning\Flask\microblog\app\templates\index.html", line 1, in top-level template code
    {% extends "base.html" %}
  File "c:\users\phuhi\onedrive - fpt software\learning\flask\microblog\venv\lib\site-packages\jinja2\environment.py", line 832, in handle_exception
    reraise(*rewrite_traceback_stack(source=source))
  File "c:\users\phuhi\onedrive - fpt software\learning\flask\microblog\venv\lib\site-packages\jinja2\_compat.py", line 28, in reraise
    raise value.with_traceback(tb)
  File "C:\Users\phuhi\OneDrive - FPT Software\Learning\Flask\microblog\app\templates\base.html", line 67, in template
    $(destElem).text("{{ _('Error: Could not contact server) }}");
jinja2.exceptions.TemplateSyntaxError: unexpected char "'" at 2677
2021-01-04 11:38:54,292 ERROR: Exception on / [GET] [in c:\users\phuhi\onedrive - fpt software\learning\flask\microblog\venv\lib\site-packages\flask\app.py:1891]
Traceback (most recent call last):
  File "c:\users\phuhi\onedrive - fpt software\learning\flask\microblog\venv\lib\site-packages\flask\app.py", line 2447, in wsgi_app
    response = self.full_dispatch_request()
  File "c:\users\phuhi\onedrive - fpt software\learning\flask\microblog\venv\lib\site-packages\flask\app.py", line 1952, in full_dispatch_request
    rv = self.handle_user_exception(e)
  File "c:\users\phuhi\onedrive - fpt software\learning\flask\microblog\venv\lib\site-packages\flask\app.py", line 1821, in handle_user_exception
    reraise(exc_type, exc_value, tb)
  File "c:\users\phuhi\onedrive - fpt software\learning\flask\microblog\venv\lib\site-packages\flask\_compat.py", line 39, in reraise
    raise value
  File "c:\users\phuhi\onedrive - fpt software\learning\flask\microblog\venv\lib\site-packages\flask\app.py", line 1950, in full_dispatch_request
    rv = self.dispatch_request()
  File "c:\users\phuhi\onedrive - fpt software\learning\flask\microblog\venv\lib\site-packages\flask\app.py", line 1936, in dispatch_request
    return self.view_functions[rule.endpoint](**req.view_args)
  File "c:\users\phuhi\onedrive - fpt software\learning\flask\microblog\venv\lib\site-packages\flask_login\utils.py", line 272, in decorated_view
    return func(*args, **kwargs)
  File "C:\Users\phuhi\OneDrive - FPT Software\Learning\Flask\microblog\app\routes.py", line 47, in index
    return render_template('index.html',title = 'Home',form=form,posts = posts.items, next_url=next_url, prev_url=prev_url)
  File "c:\users\phuhi\onedrive - fpt software\learning\flask\microblog\venv\lib\site-packages\flask\templating.py", line 137, in render_template
    return _render(
  File "c:\users\phuhi\onedrive - fpt software\learning\flask\microblog\venv\lib\site-packages\flask\templating.py", line 120, in _render
    rv = template.render(context)
  File "c:\users\phuhi\onedrive - fpt software\learning\flask\microblog\venv\lib\site-packages\jinja2\environment.py", line 1090, in render
    self.environment.handle_exception()
  File "c:\users\phuhi\onedrive - fpt software\learning\flask\microblog\venv\lib\site-packages\jinja2\environment.py", line 832, in handle_exception
    reraise(*rewrite_traceback_stack(source=source))
  File "c:\users\phuhi\onedrive - fpt software\learning\flask\microblog\venv\lib\site-packages\jinja2\_compat.py", line 28, in reraise
    raise value.with_traceback(tb)
  File "C:\Users\phuhi\OneDrive - FPT Software\Learning\Flask\microblog\app\templates\index.html", line 1, in top-level template code
    {% extends "base.html" %}
  File "c:\users\phuhi\onedrive - fpt software\learning\flask\microblog\venv\lib\site-packages\jinja2\environment.py", line 832, in handle_exception
    reraise(*rewrite_traceback_stack(source=source))
  File "c:\users\phuhi\onedrive - fpt software\learning\flask\microblog\venv\lib\site-packages\jinja2\_compat.py", line 28, in reraise
    raise value.with_traceback(tb)
  File "C:\Users\phuhi\OneDrive - FPT Software\Learning\Flask\microblog\app\templates\base.html", line 67, in template
    $(destElem).text("{{ _('Error: Could not contact server) }}");
jinja2.exceptions.TemplateSyntaxError: unexpected char "'" at 2677
