2021-01-02 22:53:01,312 ERROR: Exception on /index [GET] [in c:\users\phuhi\onedrive - fpt software\learning\flask\microblog\venv\lib\site-packages\flask\app.py:1891]
Traceback (most recent call last):
  File "c:\users\phuhi\onedrive - fpt software\learning\flask\microblog\venv\lib\site-packages\flask\app.py", line 2447, in wsgi_app
    response = self.full_dispatch_request()
  File "c:\users\phuhi\onedrive - fpt software\learning\flask\microblog\venv\lib\site-packages\flask\app.py", line 1952, in full_dispatch_request
    rv = self.handle_user_exception(e)
  File "c:\users\phuhi\onedrive - fpt software\learning\flask\microblog\venv\lib\site-packages\flask\app.py", line 1821, in handle_user_exception
    reraise(exc_type, exc_value, tb)
  File "c:\users\phuhi\onedrive - fpt software\learning\flask\microblog\venv\lib\site-packages\flask\_compat.py", line 39, in reraise
    raise value
  File "c:\users\phuhi\onedrive - fpt software\learning\flask\microblog\venv\lib\site-packages\flask\app.py", line 1950, in full_dispatch_request
    rv = self.dispatch_request()
  File "c:\users\phuhi\onedrive - fpt software\learning\flask\microblog\venv\lib\site-packages\flask\app.py", line 1936, in dispatch_request
    return self.view_functions[rule.endpoint](**req.view_args)
  File "c:\users\phuhi\onedrive - fpt software\learning\flask\microblog\venv\lib\site-packages\flask_login\utils.py", line 272, in decorated_view
    return func(*args, **kwargs)
  File "C:\Users\phuhi\OneDrive - FPT Software\Learning\Flask\microblog\app\routes.py", line 30, in index
    return render_template('index.html',title = 'Home',posts = posts)
  File "c:\users\phuhi\onedrive - fpt software\learning\flask\microblog\venv\lib\site-packages\flask\templating.py", line 137, in render_template
    return _render(
  File "c:\users\phuhi\onedrive - fpt software\learning\flask\microblog\venv\lib\site-packages\flask\templating.py", line 120, in _render
    rv = template.render(context)
  File "c:\users\phuhi\onedrive - fpt software\learning\flask\microblog\venv\lib\site-packages\jinja2\environment.py", line 1090, in render
    self.environment.handle_exception()
  File "c:\users\phuhi\onedrive - fpt software\learning\flask\microblog\venv\lib\site-packages\jinja2\environment.py", line 832, in handle_exception
    reraise(*rewrite_traceback_stack(source=source))
  File "c:\users\phuhi\onedrive - fpt software\learning\flask\microblog\venv\lib\site-packages\jinja2\_compat.py", line 28, in reraise
    raise value.with_traceback(tb)
  File "C:\Users\phuhi\OneDrive - FPT Software\Learning\Flask\microblog\app\templates\index.html", line 1, in top-level template code
    {% extends "base.html" %}
  File "C:\Users\phuhi\OneDrive - FPT Software\Learning\Flask\microblog\app\templates\base.html", line 29, in top-level template code
    {% block content %}{% endblock %}
  File "C:\Users\phuhi\OneDrive - FPT Software\Learning\Flask\microblog\app\templates\index.html", line 7, in block "content"
    {{ form.post.label}}<br>
  File "c:\users\phuhi\onedrive - fpt software\learning\flask\microblog\venv\lib\site-packages\jinja2\environment.py", line 471, in getattr
    return getattr(obj, attribute)
jinja2.exceptions.UndefinedError: 'form' is undefined
2021-01-02 22:53:48,809 INFO: Microblog startup [in C:\Users\phuhi\OneDrive - FPT Software\Learning\Flask\microblog\app\__init__.py:49]
2021-01-02 22:54:44,440 INFO: Microblog startup [in C:\Users\phuhi\OneDrive - FPT Software\Learning\Flask\microblog\app\__init__.py:49]
2021-01-02 22:54:50,222 ERROR: Exception on /index [POST] [in c:\users\phuhi\onedrive - fpt software\learning\flask\microblog\venv\lib\site-packages\flask\app.py:1891]
Traceback (most recent call last):
  File "c:\users\phuhi\onedrive - fpt software\learning\flask\microblog\venv\lib\site-packages\flask\app.py", line 2447, in wsgi_app
    response = self.full_dispatch_request()
  File "c:\users\phuhi\onedrive - fpt software\learning\flask\microblog\venv\lib\site-packages\flask\app.py", line 1952, in full_dispatch_request
    rv = self.handle_user_exception(e)
  File "c:\users\phuhi\onedrive - fpt software\learning\flask\microblog\venv\lib\site-packages\flask\app.py", line 1821, in handle_user_exception
    reraise(exc_type, exc_value, tb)
  File "c:\users\phuhi\onedrive - fpt software\learning\flask\microblog\venv\lib\site-packages\flask\_compat.py", line 39, in reraise
    raise value
  File "c:\users\phuhi\onedrive - fpt software\learning\flask\microblog\venv\lib\site-packages\flask\app.py", line 1950, in full_dispatch_request
    rv = self.dispatch_request()
  File "c:\users\phuhi\onedrive - fpt software\learning\flask\microblog\venv\lib\site-packages\flask\app.py", line 1936, in dispatch_request
    return self.view_functions[rule.endpoint](**req.view_args)
  File "c:\users\phuhi\onedrive - fpt software\learning\flask\microblog\venv\lib\site-packages\flask_login\utils.py", line 272, in decorated_view
    return func(*args, **kwargs)
  File "C:\Users\phuhi\OneDrive - FPT Software\Learning\Flask\microblog\app\routes.py", line 23, in index
    post = Post(body = form.post.data, author = current_user)
NameError: name 'Post' is not defined
2021-01-02 22:55:31,342 INFO: Microblog startup [in C:\Users\phuhi\OneDrive - FPT Software\Learning\Flask\microblog\app\__init__.py:49]
2021-01-02 23:01:53,056 INFO: Microblog startup [in C:\Users\phuhi\OneDrive - FPT Software\Learning\Flask\microblog\app\__init__.py:49]
2021-01-02 23:23:12,535 INFO: Microblog startup [in C:\Users\phuhi\OneDrive - FPT Software\Learning\Flask\microblog\app\__init__.py:49]
2021-01-02 23:23:24,067 ERROR: Exception on /explore [GET] [in c:\users\phuhi\onedrive - fpt software\learning\flask\microblog\venv\lib\site-packages\flask\app.py:1891]
Traceback (most recent call last):
  File "c:\users\phuhi\onedrive - fpt software\learning\flask\microblog\venv\lib\site-packages\flask\app.py", line 2447, in wsgi_app
    response = self.full_dispatch_request()
  File "c:\users\phuhi\onedrive - fpt software\learning\flask\microblog\venv\lib\site-packages\flask\app.py", line 1952, in full_dispatch_request
    rv = self.handle_user_exception(e)
  File "c:\users\phuhi\onedrive - fpt software\learning\flask\microblog\venv\lib\site-packages\flask\app.py", line 1821, in handle_user_exception
    reraise(exc_type, exc_value, tb)
  File "c:\users\phuhi\onedrive - fpt software\learning\flask\microblog\venv\lib\site-packages\flask\_compat.py", line 39, in reraise
    raise value
  File "c:\users\phuhi\onedrive - fpt software\learning\flask\microblog\venv\lib\site-packages\flask\app.py", line 1950, in full_dispatch_request
    rv = self.dispatch_request()
  File "c:\users\phuhi\onedrive - fpt software\learning\flask\microblog\venv\lib\site-packages\flask\app.py", line 1936, in dispatch_request
    return self.view_functions[rule.endpoint](**req.view_args)
  File "c:\users\phuhi\onedrive - fpt software\learning\flask\microblog\venv\lib\site-packages\flask_login\utils.py", line 272, in decorated_view
    return func(*args, **kwargs)
  File "C:\Users\phuhi\OneDrive - FPT Software\Learning\Flask\microblog\app\routes.py", line 159, in explore
    posts = Post.query.order_by(Post.timestamp.desc()).paginate(page, app.config['POST_PER_PAGE'],False)
KeyError: 'POST_PER_PAGE'
2021-01-02 23:24:49,190 INFO: Microblog startup [in C:\Users\phuhi\OneDrive - FPT Software\Learning\Flask\microblog\app\__init__.py:49]
2021-01-02 23:35:45,820 INFO: Microblog startup [in C:\Users\phuhi\OneDrive - FPT Software\Learning\Flask\microblog\app\__init__.py:49]
2021-01-02 23:40:37,608 INFO: Microblog startup [in C:\Users\phuhi\OneDrive - FPT Software\Learning\Flask\microblog\app\__init__.py:49]
2021-01-02 23:40:42,217 ERROR: Exception on /user/hienhp [GET] [in c:\users\phuhi\onedrive - fpt software\learning\flask\microblog\venv\lib\site-packages\flask\app.py:1891]
Traceback (most recent call last):
  File "c:\users\phuhi\onedrive - fpt software\learning\flask\microblog\venv\lib\site-packages\flask\app.py", line 2447, in wsgi_app
    response = self.full_dispatch_request()
  File "c:\users\phuhi\onedrive - fpt software\learning\flask\microblog\venv\lib\site-packages\flask\app.py", line 1952, in full_dispatch_request
    rv = self.handle_user_exception(e)
  File "c:\users\phuhi\onedrive - fpt software\learning\flask\microblog\venv\lib\site-packages\flask\app.py", line 1821, in handle_user_exception
    reraise(exc_type, exc_value, tb)
  File "c:\users\phuhi\onedrive - fpt software\learning\flask\microblog\venv\lib\site-packages\flask\_compat.py", line 39, in reraise
    raise value
  File "c:\users\phuhi\onedrive - fpt software\learning\flask\microblog\venv\lib\site-packages\flask\app.py", line 1950, in full_dispatch_request
    rv = self.dispatch_request()
  File "c:\users\phuhi\onedrive - fpt software\learning\flask\microblog\venv\lib\site-packages\flask\app.py", line 1936, in dispatch_request
    return self.view_functions[rule.endpoint](**req.view_args)
  File "c:\users\phuhi\onedrive - fpt software\learning\flask\microblog\venv\lib\site-packages\flask_login\utils.py", line 272, in decorated_view
    return func(*args, **kwargs)
  File "C:\Users\phuhi\OneDrive - FPT Software\Learning\Flask\microblog\app\routes.py", line 87, in user
    if post.has_next else None
NameError: name 'post' is not defined
