2021-01-02 22:41:59,837 ERROR: Exception on /follow/hienhp2 [POST] [in c:\users\phuhi\onedrive - fpt software\learning\flask\microblog\venv\lib\site-packages\flask\app.py:1891]
Traceback (most recent call last):
  File "c:\users\phuhi\onedrive - fpt software\learning\flask\microblog\venv\lib\site-packages\flask\app.py", line 2447, in wsgi_app
    response = self.full_dispatch_request()
  File "c:\users\phuhi\onedrive - fpt software\learning\flask\microblog\venv\lib\site-packages\flask\app.py", line 1952, in full_dispatch_request
    rv = self.handle_user_exception(e)
  File "c:\users\phuhi\onedrive - fpt software\learning\flask\microblog\venv\lib\site-packages\flask\app.py", line 1821, in handle_user_exception
    reraise(exc_type, exc_value, tb)
  File "c:\users\phuhi\onedrive - fpt software\learning\flask\microblog\venv\lib\site-packages\flask\_compat.py", line 39, in reraise
    raise value
  File "c:\users\phuhi\onedrive - fpt software\learning\flask\microblog\venv\lib\site-packages\flask\app.py", line 1950, in full_dispatch_request
    rv = self.dispatch_request()
  File "c:\users\phuhi\onedrive - fpt software\learning\flask\microblog\venv\lib\site-packages\flask\app.py", line 1936, in dispatch_request
    return self.view_functions[rule.endpoint](**req.view_args)
  File "c:\users\phuhi\onedrive - fpt software\learning\flask\microblog\venv\lib\site-packages\flask_login\utils.py", line 272, in decorated_view
    return func(*args, **kwargs)
  File "C:\Users\phuhi\OneDrive - FPT Software\Learning\Flask\microblog\app\routes.py", line 128, in follow
    return redirect(url_for('user'),username = username)
  File "c:\users\phuhi\onedrive - fpt software\learning\flask\microblog\venv\lib\site-packages\flask\helpers.py", line 370, in url_for
    return appctx.app.handle_url_build_error(error, endpoint, values)
  File "c:\users\phuhi\onedrive - fpt software\learning\flask\microblog\venv\lib\site-packages\flask\app.py", line 2216, in handle_url_build_error
    reraise(exc_type, exc_value, tb)
  File "c:\users\phuhi\onedrive - fpt software\learning\flask\microblog\venv\lib\site-packages\flask\_compat.py", line 39, in reraise
    raise value
  File "c:\users\phuhi\onedrive - fpt software\learning\flask\microblog\venv\lib\site-packages\flask\helpers.py", line 357, in url_for
    rv = url_adapter.build(
  File "c:\users\phuhi\onedrive - fpt software\learning\flask\microblog\venv\lib\site-packages\werkzeug\routing.py", line 2179, in build
    raise BuildError(endpoint, values, method, self)
werkzeug.routing.BuildError: Could not build url for endpoint 'user'. Did you forget to specify values ['username']?
2021-01-02 22:43:19,033 INFO: Microblog startup [in C:\Users\phuhi\OneDrive - FPT Software\Learning\Flask\microblog\app\__init__.py:49]
2021-01-02 22:43:32,453 ERROR: Exception on /unfollow/hienhp2 [POST] [in c:\users\phuhi\onedrive - fpt software\learning\flask\microblog\venv\lib\site-packages\flask\app.py:1891]
Traceback (most recent call last):
  File "c:\users\phuhi\onedrive - fpt software\learning\flask\microblog\venv\lib\site-packages\flask\app.py", line 2447, in wsgi_app
    response = self.full_dispatch_request()
  File "c:\users\phuhi\onedrive - fpt software\learning\flask\microblog\venv\lib\site-packages\flask\app.py", line 1952, in full_dispatch_request
    rv = self.handle_user_exception(e)
  File "c:\users\phuhi\onedrive - fpt software\learning\flask\microblog\venv\lib\site-packages\flask\app.py", line 1821, in handle_user_exception
    reraise(exc_type, exc_value, tb)
  File "c:\users\phuhi\onedrive - fpt software\learning\flask\microblog\venv\lib\site-packages\flask\_compat.py", line 39, in reraise
    raise value
  File "c:\users\phuhi\onedrive - fpt software\learning\flask\microblog\venv\lib\site-packages\flask\app.py", line 1950, in full_dispatch_request
    rv = self.dispatch_request()
  File "c:\users\phuhi\onedrive - fpt software\learning\flask\microblog\venv\lib\site-packages\flask\app.py", line 1936, in dispatch_request
    return self.view_functions[rule.endpoint](**req.view_args)
  File "c:\users\phuhi\onedrive - fpt software\learning\flask\microblog\venv\lib\site-packages\flask_login\utils.py", line 272, in decorated_view
    return func(*args, **kwargs)
  File "C:\Users\phuhi\OneDrive - FPT Software\Learning\Flask\microblog\app\routes.py", line 149, in unfollow
    return redirect(url_for('user'),username = username)
  File "c:\users\phuhi\onedrive - fpt software\learning\flask\microblog\venv\lib\site-packages\flask\helpers.py", line 370, in url_for
    return appctx.app.handle_url_build_error(error, endpoint, values)
  File "c:\users\phuhi\onedrive - fpt software\learning\flask\microblog\venv\lib\site-packages\flask\app.py", line 2216, in handle_url_build_error
    reraise(exc_type, exc_value, tb)
  File "c:\users\phuhi\onedrive - fpt software\learning\flask\microblog\venv\lib\site-packages\flask\_compat.py", line 39, in reraise
    raise value
  File "c:\users\phuhi\onedrive - fpt software\learning\flask\microblog\venv\lib\site-packages\flask\helpers.py", line 357, in url_for
    rv = url_adapter.build(
  File "c:\users\phuhi\onedrive - fpt software\learning\flask\microblog\venv\lib\site-packages\werkzeug\routing.py", line 2179, in build
    raise BuildError(endpoint, values, method, self)
werkzeug.routing.BuildError: Could not build url for endpoint 'user'. Did you forget to specify values ['username']?
2021-01-02 22:43:52,900 INFO: Microblog startup [in C:\Users\phuhi\OneDrive - FPT Software\Learning\Flask\microblog\app\__init__.py:49]
2021-01-02 22:52:31,627 INFO: Microblog startup [in C:\Users\phuhi\OneDrive - FPT Software\Learning\Flask\microblog\app\__init__.py:49]
2021-01-02 22:52:34,238 ERROR: Exception on /index [GET] [in c:\users\phuhi\onedrive - fpt software\learning\flask\microblog\venv\lib\site-packages\flask\app.py:1891]
Traceback (most recent call last):
  File "c:\users\phuhi\onedrive - fpt software\learning\flask\microblog\venv\lib\site-packages\flask\app.py", line 2447, in wsgi_app
    response = self.full_dispatch_request()
  File "c:\users\phuhi\onedrive - fpt software\learning\flask\microblog\venv\lib\site-packages\flask\app.py", line 1952, in full_dispatch_request
    rv = self.handle_user_exception(e)
  File "c:\users\phuhi\onedrive - fpt software\learning\flask\microblog\venv\lib\site-packages\flask\app.py", line 1821, in handle_user_exception
    reraise(exc_type, exc_value, tb)
  File "c:\users\phuhi\onedrive - fpt software\learning\flask\microblog\venv\lib\site-packages\flask\_compat.py", line 39, in reraise
    raise value
  File "c:\users\phuhi\onedrive - fpt software\learning\flask\microblog\venv\lib\site-packages\flask\app.py", line 1950, in full_dispatch_request
    rv = self.dispatch_request()
  File "c:\users\phuhi\onedrive - fpt software\learning\flask\microblog\venv\lib\site-packages\flask\app.py", line 1936, in dispatch_request
    return self.view_functions[rule.endpoint](**req.view_args)
  File "c:\users\phuhi\onedrive - fpt software\learning\flask\microblog\venv\lib\site-packages\flask_login\utils.py", line 272, in decorated_view
    return func(*args, **kwargs)
  File "C:\Users\phuhi\OneDrive - FPT Software\Learning\Flask\microblog\app\routes.py", line 20, in index
    form = PostForm(request.form)
NameError: name 'PostForm' is not defined
2021-01-02 22:52:58,857 INFO: Microblog startup [in C:\Users\phuhi\OneDrive - FPT Software\Learning\Flask\microblog\app\__init__.py:49]
